Workbook

Sheet LGR CCEE CSR
G1: Planilla Tipo: MRMPA
G3: Plan de Mantenimiento Preventivo Año: 2026
G4: Kilometraje anual previsto a recorrer: 12.105.546
E6: TIPO DE VEHÍCULO: | G6: Coche Eléctrico CSR
A8: Km. al: 30/09/2025 | C8: Última R.G. | E8: Última Revisión | H8: AÑO 2026
A9: Marca-Modelo | B9: Módulo | C9: Km. | D9: Fecha | E9: Km. | F9: Tipo | G9: Fecha | H9: ENE. | I9: FEB. | J9: MAR. | K9: ABR. | L9: MAY. | M9: JUN. | N9: JUL. | O9: AGO. | P9: SEP. | Q9: OCT. | R9: NOV. | S9: DIC.
A10: CSR | B10: MOD 01 | C10: 1254339 | D10: 43008 | E10: 1398 | F10: Q | G10: 45928 | Q10: BA
A11: CSR | B11: MOD 02 | C11: 1278496 | D11: 42247 | E11: 2955 | F11: Q | G11: 45923 | L11: D
A12: CSR | B12: MOD 03 | C12: 1436440 | D12: 42308 | E12: 2431 | F12: Q | G12: 45924 | L12: A
A13: CSR | B13: MOD 04 | C13: 1436491 | D13: 42277 | E13: 1346 | F13: Q | G13: 45927 | N13: D
A14: CSR | B14: MOD 05 | C14: 1366839 | D14: 42613 | E14: 5197 | F14: Q | G14: 45917 | K14: BA
A15: CSR | B15: MOD 06 | C15: 1386740 | D15: 42247 | E15: 1 | F15: Q | G15: 45930 | K15: D
A16: CSR | B16: MOD 07 | C16: 1412990 | D16: 42247 | E16: 2969 | F16: Q | G16: 45923 | K16: D
A17: CSR | B17: MOD 08 | C17: 1407691 | D17: 42613 | E17: 6400 | F17: B | G17: 45916
A18: CSR | B18: MOD 09 | C18: 1390992 | D18: 42582 | E18: 2494 | F18: Q | G18: 45924
A19: CSR | B19: MOD 10 | C19: 1411133 | D19: 42582 | E19: 3532 | F19: Q | G19: 45922
A20: CSR | B20: MOD 11 | C20: 1411071 | D20: 42277 | E20: 1072 | F20: Q | G20: 45928 | I20: A | P20: D
A21: CSR | B21: MOD 12 | C21: 1406937 | D21: 42308 | E21: 1183 | F21: A | G21: 45925 | R21: BA
A22: CSR | B22: MOD 13 | C22: 1413986 | D22: 42460 | E22: 3085 | F22: Q | G22: 45923 | N22: A
A23: CSR | B23: MOD 14 | C23: 1307964 | D23: 42277 | E23: 1428 | F23: Q | G23: 45926 | O23: BA
A24: CSR | B24: MOD 15 | C24: 1404415 | D24: 42400 | E24: 897 | F24: Q | G24: 45929 | O24: A
A25: CSR | B25: MOD 16 | C25: 1372997 | D25: 42277 | E25: 4486 | F25: B | G25: 45920 | I25: BA | Q25: D
A26: CSR | B26: MOD 17 | C26: 1382526 | D26: 42277 | E26: 3375 | F26: B | G26: 45924 | I26: BA | Q26: D
A27: CSR | B27: MOD 18 | C27: 1400193 | D27: 42460 | E27: 5184 | F27: Q | G27: 45915 | R27: A
A28: CSR | B28: MOD 19 | C28: 1332970 | D28: 42277 | E28: 3215 | F28: Q | G28: 45922 | L28: BA | S28: D
A29: CSR | B29: MOD 20 | C29: 1421985 | D29: 42400 | E29: 4521 | F29: Q | G29: 45921 | M29: A
A30: CSR | B30: MOD 21 | C30: 1383960 | D30: 42674 | E30: 1663 | F30: B | G30: 45926
A31: CSR | B31: MOD 22 | C31: 1408722 | D31: 42551 | E31: 508 | F31: Q | G31: 45930 | O31: A
A32: CSR | B32: MOD 23 | C32: 1403983 | D32: 42308 | E32: 1827 | F32: Q | G32: 45925 | L32: A
A33: CSR | B33: MOD 24 | C33: 1315773 | D33: 42277 | E33: 565 | F33: Q | G33: 45930 | M33: BA | S33: D
A34: CSR | B34: MOD 25 | C34: 1339524 | D34: 42277 | E34: 6035 | F34: Q | G34: 45917 | M34: BA | R34: D
A35: CSR | B35: MOD 26 | C35: 1388476 | D35: 42277 | E35: 2331 | F35: Q | G35: 45926 | L35: A | P35: D
A36: CSR | B36: MOD 27 | C36: 1440939 | D36: 42277 | E36: 6001 | F36: B | G36: 45917 | M36: D
A37: CSR | B37: MOD 28 | C37: 1429568 | D37: 42277 | E37: 5998 | F37: Q | G37: 45918 | N37: D
A38: CSR | B38: MOD 29 | C38: 1406946 | D38: 42400 | E38: 5088 | F38: B | G38: 45918 | P38: A
A39: CSR | B39: MOD 30 | C39: 1450222 | D39: 42277 | E39: 1050 | F39: Q | G39: 45929 | L39: D
A40: CSR | B40: MOD 31 | C40: 1292491 | D40: 42916 | E40: 4409 | F40: B | G40: 45922 | N40: BA
A41: CSR | B41: MOD 32 | C41: 1393302 | D41: 42400 | E41: 3977 | F41: Q | G41: 45911 | S41: A
A42: CSR | B42: MOD 33 | C42: 1425799 | D42: 42277 | E42: 4314 | F42: Q | G42: 45920 | K42: A | O42: D
A43: CSR | B43: MOD 34 | C43: 1448478 | D43: 42277 | E43: 4582 | F43: Q | G43: 45920 | I43: A | M43: D
...

Sheet LGR RESUMEN CCEE CSR
G1: Planilla Tipo: MRAM (2)
G3: Avance de Mantenimiento Preventivo
F5: AVANCE DE TAREAS REALIZADAS AL MES DE: | L5: (a)___________________
I6: TIPO DE VEHÍCULO: | L6: Coche Eléctrico CSR
C8: CANTIDAD DE INTERVENCIONES
A10: Tipo de Revisión | B10: Período | C10: ENERO | E10: FEBRERO | G10: MARZO | I10: ABRIL | K10: MAYO | M10: JUNIO | O10: JULIO | Q10: AGOSTO | S10: SEPTIEMBRE | U10: OCTUBRE | W10: NOVIEMBRE | Y10: DICIEMBRE | AA10: TOTAL
C11: Prog. | D11: Realiz. | E11: Prog. | F11: Realiz. | G11: Prog. | H11: Realiz. | I11: Prog. | J11: Realiz. | K11: Prog. | L11: Realiz. | M11: Prog. | N11: Realiz. | O11: Prog. | P11: Realiz. | Q11: Prog. | R11: Realiz. | S11: Prog. | T11: Realiz. | U11: Prog. | V11: Realiz. | W11: Prog. | X11: Realiz. | Y11: Prog. | Z11: Realiz. | AA11: Prog. | AB11: Realiz.
A12: Revisión Quincenal | B12: 15 Días / 6.250 Km. | C12: 121 | E12: 121 | G12: 121 | I12: 121 | K12: 121 | M12: 121 | O12: 121 | Q12: 121 | S12: 121 | U12: 121 | W12: 121 | Y12: 121 | AA12: =SUM(C12+E12+G12+I12+K12+M12+O12+Q12+S12+U12+W12+Y12) -> 1452 | AB12: =+D12+F12+H12+J12+L12+N12+P12+R12+T12+V12+X12+Z12 -> 0
A13: Revisión Bimestral | B13: 2 Meses / 25.000 Km. | C13: 36 | E13: 36 | G13: 36 | I13: 36 | K13: 36 | M13: 36 | O13: 36 | Q13: 36 | S13: 36 | U13: 36 | W13: 36 | Y13: 36 | AA13: =SUM(C13+E13+G13+I13+K13+M13+O13+Q13+S13+U13+W13+Y13) -> 432 | AB13: =+D13+F13+H13+J13+L13+N13+P13+R13+T13+V13+X13+Z13 -> 0
A14: Revisión Anual | B14: 15 Meses / 187.500 Km. | C14: 3 | E14: 4 | G14: 0 | I14: 2 | K14: 3 | M14: 1 | O14: 4 | Q14: 2 | S14: 2 | U14: 2 | W14: 1 | Y14: 3 | AA14: =SUM(C14+E14+G14+I14+K14+M14+O14+Q14+S14+U14+W14+Y14) -> 27 | AB14: =+D14+F14+H14+J14+L14+N14+P14+R14+T14+V14+X14+Z14 -> 0
A15: Revisión Bianual | B15: 2,5 Años / 375.000 Km. | C15: 1 | E15: 2 | G15: 4 | I15: 3 | K15: 3 | M15: 5 | O15: 3 | Q15: 4 | S15: 5 | U15: 3 | W15: 3 | Y15: 1 | AA15: =SUM(C15+E15+G15+I15+K15+M15+O15+Q15+S15+U15+W15+Y15) -> 37 | AB15: =+D15+F15+H15+J15+L15+N15+P15+R15+T15+V15+X15+Z15 -> 0
A16: Reparación Pentanual | B16: 5 Años / 750.000 Km. | C16: 0 | E16: 0 | G16: 0 | I16: 0 | K16: 0 | M16: 0 | O16: 0 | Q16: 0 | S16: 0 | U16: 0 | W16: 0 | Y16: 0 | AA16: =SUM(C16+E16+G16+I16+K16+M16+O16+Q16+S16+U16+W16+Y16) -> 0 | AB16: =+D16+F16+H16+J16+L16+N16+P16+R16+T16+V16+X16+Z16 -> 0
A17: Reparación Decanual | B17: 10 Años / 1.500.000 Km. | C17: 0 | E17: 0 | G17: 0 | I17: 2 | K17: 2 | M17: 2 | O17: 2 | Q17: 2 | S17: 2 | U17: 2 | W17: 2 | Y17: 2 | AA17: =SUM(C17+E17+G17+I17+K17+M17+O17+Q17+S17+U17+W17+Y17) -> 18 | AB17: =+D17+F17+H17+J17+L17+N17+P17+R17+T17+V17+X17+Z17 -> 0

Sheet LGR CCEE
G1: Planilla Tipo: MRMPA
G3: ='LGR CCEE CSR'!G3:K3 -> Plan de Mantenimiento Preventivo Año: 2026
G4: Kilometraje anual previsto a recorrer: 2.269.957
E6: TIPO DE VEHÍCULO: | G6: Coche Eléctrico Toshiba
A8: ='LGR CCEE CSR'!A8 -> Km. al: 30/09/2025 | C8: Última R.G. | E8: Última Revisión | H8: =+'LGR CCEE CSR'!H8:S8 -> AÑO 2026
A9: Marca-Modelo | B9: Módulo | C9: Km. | D9: Fecha | E9: Km. | F9: Tipo | G9: Fecha | H9: ENE. | I9: FEB. | J9: MAR. | K9: ABR. | L9: MAY. | M9: JUN. | N9: JUL. | O9: AGO. | P9: SEP. | Q9: OCT. | R9: NOV. | S9: DIC.
A10: TOSHIBA | B10: MOD 04 | C10: 161294 | D10: 45275 | E10: 21002 | F10: MEN | G10: 45865
A11: TOSHIBA | B11: MOD 06 | C11: 243297 | D11: 45056 | E11: 21160 | F11: MEN | G11: 45865
A12: TOSHIBA | B12: MOD 09 | C12: 1 | D12: 45944 | E12: 2379 | F12: IS | G12: 45986
A13: TOSHIBA | B13: MOD 11 | C13: 663718 | D13: 43539 | E13: 8409 | F13: MEN | G13: 45882
A14: TOSHIBA | B14: MOD 12 | C14: - Detenido en Reparación General desde fecha 01/04/25 - | I14: RG
A15: TOSHIBA | B15: MOD 15 | C15: 674428 | D15: 43384 | E15: 8440 | F15: MEN | G15: 45882
A16: TOSHIBA | B16: MOD 16 | C16: 800382 | D16: 42993 | E16: 13754 | F16: MEN | G16: 45892 | S16: RG
A17: TOSHIBA | B17: MOD 19 | C17: - Detenido en Reparación General desde fecha 04/02/25 - | L17: RG
A18: TOSHIBA | B18: MOD 20 | C18: 319215 | D18: 44540 | E18: 796 | F18: MEN | G18: 45922
A19: TOSHIBA | B19: MOD 21 | C19: 479266 | D19: 44071 | E19: 5488 | F19: MEN | G19: 45912
A20: TOSHIBA | B20: MOD 22 | C20: 569592 | D20: 43885 | E20: 13314 | F20: MEN | G20: 45872
A21: TOSHIBA | B21: MOD 24 | C21: 433915 | D21: 44194 | E21: 26326 | F21: MEN | G21: 45834
A22: TOSHIBA | B22: MOD 28 | C22: 614013 | D22: 43812 | E22: 8055 | F22: MEN | G22: 45903
A23: TOSHIBA | B23: MOD 29 | C23: 265553 | D23: 44902 | E23: 8124 | F23: MEN | G23: 45903
A24: TOSHIBA | B24: MOD 31 | C24: 313120 | D24: 44788 | E24: 25569 | F24: MEN | G24: 45848
A25: TOSHIBA | B25: MOD 34 | C25: 795092 | D25: 43048 | E25: 13349 | F25: MEN | G25: 45872
A26: TOSHIBA | B26: MOD 36 | C26: 200941 | D26: 45169 | E26: 25401 | F26: MEN | G26: 45848
A27: TOSHIBA | B27: MOD39 | C27: 384232 | D27: 44400 | E27: 5433 | F27: MEN | G27: 45912
A28: TOSHIBA | B28: MOD 40 | C28: - Detenido en Reparación General desde fecha 01/04/25 - | O28: RG
A29: TOSHIBA | B29: MOD 43 | C29: 329956 | D29: 44693 | E29: 25821 | F29: MEN | G29: 45834
A30: TOSHIBA | B30: MOD 45 | C30: 1 | D30: 45944 | E30: 2651 | F30: IS | G30: 45980
A31: TOSHIBA | B31: MOD 46 | C31: 74041 | D31: 45665 | E31: 785 | F31: MEN | G31: 45922
A32: TOSHIBA | B32: MOD 47 | C32: 692528 | D32: 43520 | E32: 13759 | F32: MEN | G32: 45892
A33: TOSHIBA | B33: MOD 49 | C33: 610375 | D33: 43707 | E33: 19796 | F33: MEN | G33: 45856
A34: TOSHIBA | B34: MOD 52 | C34: 101367 | D34: 45534 | E34: 19734 | F34: MEN | G34: 45856
G36: RB | H36: =COUNTIF(H10:H34,"RB") -> 0 | I36: =COUNTIF(I10:I34,"RB") -> 0 | J36: =COUNTIF(J10:J34,"RB") -> 0 | K36: =COUNTIF(K10:K34,"RB") -> 0 | L36: =COUNTIF(L10:L34,"RB") -> 0 | M36: =COUNTIF(M10:M34,"RB") -> 0 | N36: =COUNTIF(N10:N34,"RB") -> 0 | O36: =COUNTIF(O10:O34,"RB") -> 0 | ... S36: =COUNTIF(S10:S34,"RB") -> 0 | T36: =SUM(H36:S36) -> 0
G37: RG | H37: =COUNTIF(H10:H34,"RG") -> 0 | I37: =COUNTIF(I10:I34,"RG") -> 1 | J37: =COUNTIF(J10:J34,"RG") -> 0 | K37: =COUNTIF(K10:K34,"RG") -> 0 | L37: =COUNTIF(L10:L34,"RG") -> 1 | M37: =COUNTIF(M10:M34,"RG") -> 0 | N37: =COUNTIF(N10:N34,"RG") -> 0 | O37: =COUNTIF(O10:O34,"RG") -> 1 | ... S37: =COUNTIF(S10:S34,"RG") -> 1 | T37: =SUM(H37:S37) -> 4

Sheet LGR RESUMEN CCEE
G1: Planilla Tipo: MRAM (2)
G3: Avance de Mantenimiento Preventivo
F5: AVANCE DE TAREAS REALIZADAS AL MES DE: | L5: (a)___________________
I6: TIPO DE VEHÍCULO: | L6: Coche Eléctrico Toshiba
C8: CANTIDAD DE INTERVENCIONES
A10: Tipo de Revisión | B10: Período | C10: ENERO | E10: FEBRERO | G10: MARZO | I10: ABRIL | K10: MAYO | M10: JUNIO | O10: JULIO | Q10: AGOSTO | S10: SEPTIEMBRE | U10: OCTUBRE | W10: NOVIEMBRE | Y10: DICIEMBRE | AA10: TOTAL
C11: Prog. | D11: Realiz. | E11: Prog. | F11: Realiz. | G11: Prog. | H11: Realiz. | I11: Prog. | J11: Realiz. | K11: Prog. | L11: Realiz. | M11: Prog. | N11: Realiz. | O11: Prog. | P11: Realiz. | Q11: Prog. | R11: Realiz. | S11: Prog. | T11: Realiz. | U11: Prog. | V11: Realiz. | W11: Prog. | X11: Realiz. | Y11: Prog. | Z11: Realiz. | AA11: Prog. | AB11: Realiz.
A12: Revisióm Mensual | B12: 30.000 Km. | C12: 6 | E12: 6 | G12: 6 | I12: 6 | K12: 6 | M12: 6 | O12: 6 | Q12: 6 | S12: 6 | U12: 6 | W12: 6 | Y12: 6 | AA12: =SUM(C12+E12+G12+I12+K12+M12+O12+Q12+S12+U12+W12+Y12) -> 72 | AB12: =+D12+F12+H12+J12+L12+N12+P12+R12+T12+V12+X12+Z12 -> 0
A13: Reparación Bienal | B13: 300.000 Km. | C13: 0 | E13: 0 | G13: 0 | I13: 0 | K13: 0 | M13: 0 | O13: 0 | Q13: 0 | S13: 0 | U13: 0 | W13: 0 | Y13: 0 | AA13: =SUM(C13+E13+G13+I13+K13+M13+O13+Q13+S13+U13+W13+Y13) -> 0 | AB13: =+D13+F13+H13+J13+L13+N13+P13+R13+T13+V13+X13+Z13 -> 0
A14: Reparación General | B14: 600.000 Km. | C14: 0 | E14: 1 | G14: 0 | I14: 0 | K14: 1 | M14: 0 | O14: 0 | Q14: 1 | S14: 0 | U14: 0 | W14: 0 | Y14: 1 | AA14: =SUM(C14+E14+G14+I14+K14+M14+O14+Q14+S14+U14+W14+Y14) -> 4 | AB14: =+D14+F14+H14+J14+L14+N14+P14+R14+T14+V14+X14+Z14 -> 0

Sheet LGR LOCS
G1: Planilla Tipo: MRMPA
G3: ='LGR CCEE'!G3:K3 -> Plan de Mantenimiento Preventivo Año: 2026
G4: Kilometraje anual previsto a recorrer: 1.262.706
E5: MES de: | G5: (a)___________________
E6: TIPO DE VEHÍCULO: | G6: Locomotora GM
A8: ='LGR CCEE'!A8 -> Km. al: 30/09/2025 | C8: Última R.G. | E8: Última Revisión | H8: ='LGR CCEE'!H8:S8 -> AÑO 2026
A9: Marca-Modelo | B9: Número | C9: Km. | D9: Fecha | E9: Km. | F9: Tipo | G9: Fecha | H9: ENE. | I9: FEB. | J9: MAR. | K9: ABR. | L9: MAY. | M9: JUN. | N9: JUL. | O9: AGO. | P9: SEP. | Q9: OCT. | R9: NOV. | S9: DIC.
A10: G.M. G22 CW | B10: A 703 | C10: 935368 | D10: 41272 | E10: 14702 | F10: A | G10: 45848 | J10: ABC + BV
A11: G.M. G22 CW | B11: A 710 | C11: 152271 | D11: 44488 | E11: 15267 | F11: A | G11: 45715 | L11: N1
A12: G.M. GT22 CW | B12: A 900 | C12: 1356729 | D12: 40794 | E12: 10620 | F12: A | G12: 45904
A13: G.M. GT22 CW | B13: A 904 | C13: 1632201 | D13: 39836 | E13: 8917 | F13: A | G13: 45897 | M13: ABC
A14: G.M. GT22 CW-2 | B14: A 908 | C14: 693954 | D14: 41656 | E14: 9626 | F14: A | G14: 45907
A15: G.M. GT22 CW-2 | B15: A 909 | C15: 1470199 | D15: 40002 | E15: 1743 | F15: AB | G15: 45924 | I15: ABC + BV
A16: G.M. GT22 CW-2 | B16: A 910 | C16: 759403 | D16: 42221 | E16: 9007 | F16: A | G16: 45818 | I16: N4
A17: G.M. GT22 CW-2 | B17: A 911 | C17: 1321075 | D17: 41231 | E17: 14524 | F17: A | G17: 45894 | L17: ABC + BV
A18: G.M. GT22 CW-2 | B18: A 912 | C18: 928967 | D18: 41823 | E18: 1011 | F18: ABC | G18: 45923 | S18: N5
A19: G.M. GT22 CW-2 | B19: A 913 | C19: 994460 | D19: 41641 | E19: 7389 | F19: ABC | G19: 45887 | P19: N5
A20: G.M. GT22 CW-2 | B20: A 914 | C20: 804230 | D20: 42062 | E20: 982 | F20: ABC | G20: 45891 | Q20: N4
A21: G.M. GT22 CW-2 | B21: A 915 | C21: - Detenida en Reparación Numeral 3 desde fecha 16/09/25 - | H21: N3
A22: G.M. GT22 CW-2 | B22: A 917 | C22: 947315 | D22: 42013 | E22: 10215 | F22: ABC | G22: 45892 | R22: N5
A23: G.M. GT22 CW-2 | B23: A 918 | C23: 605703 | D23: 43242 | E23: 15125 | F23: AB | G23: 45873 | N23: N3
A24: G.M. GT22 CW-2 | B24: A 919 | C24: 656408 | D24: 43675 | E24: 1894 | F24: A | G24: 45916 | M24: ABC
A25: G.M. GT22 CW-2 | B25: A 920 | C25: 1211264 | D25: 41396 | E25: 5603 | F25: A | G25: 45901 | R25: ABC + BV
A26: G.M. GT22 CW-2 | B26: A 922 | C26: 795094 | D26: 42636 | E26: 71 | F26: A | G26: 45928 | N26: N4
A27: G.M. GT22 CW | B27: A925 | C27: 375936 | D27: 44216 | E27: 16656 | F27: AB | G27: 45872 | I27: N2
G28: ABC | H28: =COUNTIF(H10:H27,"ABC") -> 0 | I28: =COUNTIF(I10:I27,"ABC") -> 0 | J28: =COUNTIF(J10:J27,"ABC") -> 0 | K28: =COUNTIF(K10:K27,"ABC") -> 0 | L28: =COUNTIF(L10:L27,"ABC") -> 0 | M28: =COUNTIF(M10:M27,"ABC") -> 2 | N28: =COUNTIF(N10:N27,"ABC") -> 0 | O28: =COUNTIF(O10:O27,"ABC") -> 0 | ... S28: =COUNTIF(S10:S27,"ABC") -> 0 | T28: =SUM(H28:S28) -> 2
G29: ABC + BV | H29: =COUNTIF(H10:H27,"ABC + BV") -> 0 | I29: =COUNTIF(I10:I27,"ABC + BV") -> 1 | J29: =COUNTIF(J10:J27,"ABC + BV") -> 1 | K29: =COUNTIF(K10:K27,"ABC + BV") -> 0 | L29: =COUNTIF(L10:L27,"ABC + BV") -> 1 | M29: =COUNTIF(M10:M27,"ABC + BV") -> 0 | N29: =COUNTIF(N10:N27,"ABC + BV") -> 0 | O29: =COUNTIF(O10:O27,"ABC + BV") -> 0 | ... S29: =COUNTIF(S10:S27,"ABC + BV") -> 0 | T29: =SUM(H29:S29) -> 4
G30: ABC Total | H30: =+H29+H28 -> 0 | I30: =+I29+I28 -> 1 | J30: =+J29+J28 -> 1 | K30: =+K29+K28 -> 0 | L30: =+L29+L28 -> 1 | M30: =+M29+M28 -> 2 | N30: =+N29+N28 -> 0 | O30: =+O29+O28 -> 0 | ... T30: =+T29+T28 -> 6
G31: N1-6 | H31: =COUNTIF(H10:H27,"N*") -> 1 | I31: =COUNTIF(I10:I27,"N*") -> 2 | J31: =COUNTIF(J10:J27,"N*") -> 0 | K31: =COUNTIF(K10:K27,"N*") -> 0 | L31: =COUNTIF(L10:L27,"N*") -> 1 | M31: =COUNTIF(M10:M27,"N*") -> 0 | N31: =COUNTIF(N10:N27,"N*") -> 2 | O31: =COUNTIF(O10:O27,"N*") -> 0 | ... S31: =COUNTIF(S10:S27,"N*") -> 1 | T31: =SUM(H31:S31) -> 10
G32: RG | H32: =COUNTIF(H10:H27,"RG") -> 0 | I32: =COUNTIF(I10:I27,"RG") -> 0 | J32: =COUNTIF(J10:J27,"RG") -> 0 | K32: =COUNTIF(K10:K27,"RG") -> 0 | L32: =COUNTIF(L10:L27,"RG") -> 0 | M32: =COUNTIF(M10:M27,"RG") -> 0 | N32: =COUNTIF(N10:N27,"RG") -> 0 | O32: =COUNTIF(O10:O27,"RG") -> 0 | ... S32: =COUNTIF(S10:S27,"RG") -> 0 | T32: =SUM(H32:S32) -> 0
A34: G.M. GT22 CW | B34: 9069 | C34: 336919 | D34: 33970 | P34: RG

Sheet LGR RESUMEN LOCS
G1: Planilla Tipo: MRAM (2)
G3: Avance de Mantenimiento Preventivo
F5: AVANCE DE TAREAS REALIZADAS AL MES DE: | L5: (a)___________________
I6: TIPO DE VEHÍCULO: | L6: Locomotora GM
C8: CANTIDAD DE INTERVENCIONES
A10: Tipo de Revisión | B10: Período | C10: ENERO | E10: FEBRERO | G10: MARZO | I10: ABRIL | K10: MAYO | M10: JUNIO | O10: JULIO | Q10: AGOSTO | S10: SEPTIEMBRE | U10: OCTUBRE | W10: NOVIEMBRE | Y10: DICIEMBRE | AA10: TOTAL
C11: Prog. | D11: Realiz. | E11: Prog. | F11: Realiz. | G11: Prog. | H11: Realiz. | I11: Prog. | J11: Realiz. | K11: Prog. | L11: Realiz. | M11: Prog. | N11: Realiz. | O11: Prog. | P11: Realiz. | Q11: Prog. | R11: Realiz. | S11: Prog. | T11: Realiz. | U11: Prog. | V11: Realiz. | W11: Prog. | X11: Realiz. | Y11: Prog. | Z11: Realiz. | AA11: Prog. | AB11: Realiz.
A12: Revisión A | B12: 16.000 Km. | C12: 5 | E12: 4 | G12: 5 | I12: 4 | K12: 5 | M12: 4 | O12: 5 | Q12: 4 | S12: 4 | U12: 5 | W12: 4 | Y12: 4 | AA12: =SUM(C12+E12+G12+I12+K12+M12+O12+Q12+S12+U12+W12+Y12) -> 53 | AB12: =+D12+F12+H12+J12+L12+N12+P12+R12+T12+V12+X12+Z12 -> 0
A13: Revisión AB | B13: 50.000 Km. | C13: 1 | E13: 0 | G13: 1 | I13: 1 | K13: 1 | M13: 1 | O13: 1 | Q13: 1 | S13: 1 | U13: 1 | W13: 1 | Y13: 1 | AA13: =SUM(C13+E13+G13+I13+K13+M13+O13+Q13+S13+U13+W13+Y13) -> 11 | AB13: =+D13+F13+H13+J13+L13+N13+P13+R13+T13+V13+X13+Z13 -> 0
A14: Revisión ABC | B14: 100.000 Km. | C14: 0 | E14: 1 | G14: 1 | I14: 0 | K14: 1 | M14: 2 | O14: 0 | Q14: 0 | S14: 0 | U14: 0 | W14: 1 | Y14: 0 | AA14: =SUM(C14+E14+G14+I14+K14+M14+O14+Q14+S14+U14+W14+Y14) -> 6 | AB14: =+D14+F14+H14+J14+L14+N14+P14+R14+T14+V14+X14+Z14 -> 0
A15: Reparación Numeral | B15: 200.000 Km. | C15: 1 | E15: 2 | G15: 0 | I15: 0 | K15: 1 | M15: 0 | O15: 2 | Q15: 0 | S15: 1 | U15: 1 | W15: 1 | Y15: 1 | AA15: =SUM(C15+E15+G15+I15+K15+M15+O15+Q15+S15+U15+W15+Y15) -> 10 | AB15: =+D15+F15+H15+J15+L15+N15+P15+R15+T15+V15+X15+Z15 -> 0
A16: Reparación General | B16: 2.400.000 Km. | C16: 0 | E16: 0 | G16: 0 | I16: 0 | K16: 0 | M16: 0 | O16: 0 | Q16: 0 | S16: 0 | U16: 0 | W16: 0 | Y16: 0 | AA16: =SUM(C16+E16+G16+I16+K16+M16+O16+Q16+S16+U16+W16+Y16) -> 0 | AB16: =+D16+F16+H16+J16+L16+N16+P16+R16+T16+V16+X16+Z16 -> 0
A19: Revisión A GT22 | AA19: =SUM(C19+E19+G19+I19+K19+M19+O19+Q19+S19+U19+W19+Y19) -> 0
A20: Revisión A G22 | AA20: =SUM(C20+E20+G20+I20+K20+M20+O20+Q20+S20+U20+W20+Y20) -> 0
A22: Revisión AB GT22 | AA22: =SUM(C22+E22+G22+I22+K22+M22+O22+Q22+S22+U22+W22+Y22) -> 0
A23: Revisión AB G22 | AA23: =SUM(C23+E23+G23+I23+K23+M23+O23+Q23+S23+U23+W23+Y23) -> 0

Sheet LGR CCRR
G1: Planilla Tipo: MRMPA
G3: ='LGR CCEE'!G3:K3 -> Plan de Mantenimiento Preventivo Año: 2026
G4: Kilometraje anual previsto a recorrer: 3.470.360
E5: MES de: | G5: (a)___________________
E6: TIPO DE VEHÍCULO: | G6: Coche Remolcado
A8: =+'LGR CCEE'!A8 -> Km. al: 30/09/2025 | C8: Última R.G. | E8: Última Revisión | H8: ='LGR LOCS'!H8:S8 -> AÑO 2026
A9: Marca-Modelo | B9: Número | C9: Km. | D9: Fecha | E9: Km. | F9: Tipo | G9: Fecha | H9: ENE. | I9: FEB. | J9: MAR. | K9: ABR. | L9: MAY. | M9: JUN. | N9: JUL. | O9: AGO. | P9: SEP. | Q9: OCT. | R9: NOV. | S9: DIC.
A10: Materfer F.U. | B10: 2521 | C10: 480709.2 | D10: 43672 | E10: 0 | F10: ABC | G10: 45923 | R10: ABC+BV
A11: Materfer F.U. | B11: 2524 | C11: 18355.4 | D11: 45817 | E11: 4002.8 | F11: A | G11: 45918 | S11: ABC
A12: Materfer F.U. | B12: 2526 | C12: 483805.3 | D12: 43545 | E12: 8712.2 | F12: ABC | G12: 45841 | O12: ABC+BV
A13: Materfer F.U. | B13: 2530 | C13: 437898.7 | D13: 43165 | E13: 8782.2 | F13: AB | G13: 45873 | S13: ABC+BV
A14: Materfer F.U. | B14: 2533 | C14: 679540.8 | D14: 42185 | E14: 10059.8 | F14: AB | G14: 45798 | R14: ABC+BV
A15: Materfer F.U. | B15: 2555 | C15: 654434.5 | D15: 43097 | E15: 13760 | F15: AB | G15: 45890 | S15: ABC+BV
A16: Materfer - U. | B16: 2560
A17: Materfer F.U. | B17: 2569 | C17: 620931.5 | D17: 42947 | E17: 13050.4 | F17: AB | G17: 45826 | I17: ABC+BV
A18: Materfer F.U. | B18: 2571 | C18: 649667.7 | D18: 42341 | E18: 6331.8 | F18: AB | G18: 45881 | H18: ABC+BV
A19: Materfer F.U. | B19: 2588 | C19: 569487.4 | D19: 43286 | E19: 7213.8 | F19: ABC | G19: 45814 | O19: ABC+BV
A20: Materfer F.U. | B20: 2591 | C20: 583320 | D20: 43227 | E20: 635 | F20: ABC | G20: 45807 | N20: ABC+BV
A21: Materfer F.U. | B21: 2597 | C21: 7429.8 | D21: 45817 | E21: 7429.8 | F21: AB | G21: 45832
A22: Materfer F.U. | B22: 2598 | C22: 313842.3 | D22: 43251 | E22: 2808.4 | F22: ABC | G22: 45799 | N22: ABC+BV
A23: Materfer F.U. | B23: 2612 | C23: 531053.2 | D23: 43564 | E23: 10598.4 | F23: A | G23: 45882 | J23: ABC+BV
A24: Materfer F.U. | B24: 2615 | C24: 122163.5 | D24: 45401 | E24: 3025.2 | F24: ABC | G24: 45883
A25: Materfer F.U. | B25: 2621 | C25: 324756 | D25: 43396 | E25: 0 | F25: ABC | G25: 45924 | N25: ABC+BV
A26: Materfer F.U. | B26: 2624 | C26: 575503.9 | D26: 43370 | E26: 5560 | F26: AB | G26: 45768 | S26: ABC+BV
A27: Materfer F.U. | B27: 2626 | C27: 588762.7 | D27: 43416 | E27: 9403 | F27: A | G27: 45854 | H27: ABC+BV
A28: Materfer F.U. | B28: 2632 | C28: - Detenido en Reparación General desde fecha 03/07/25 -
A29: Materfer - U. | B29: 3019 | C29: 611711.8 | D29: 43067 | E29: 635 | F29: AB | G29: 45929 | L29: ABC+BV
A30: Materfer - U. | B30: 3022 | J30: RG
A31: Materfer - U. | B31: 3038 | C31: 455555.2 | D31: 42521 | E31: 2407.2 | F31: AB | G31: 45905 | H31: ABC+BV
A32: Materfer - U. | B32: 3203 | C32: 381331.4 | D32: 43767 | E32: 9802.4 | F32: A | G32: 45903 | R32: ABC+BV
A33: Materfer - U. | B33: 3501 | C33: 481828.4 | D33: 43616 | E33: 4641.8 | F33: ABC | G33: 45838 | N33: ABC+BV
A34: Materfer - U. | B34: 3503 | C34: 403591.4 | D34: 43711 | E34: 14729.8 | F34: AB | G34: 45874 | R34: ABC+BV
A35: Materfer - U. | B35: 3504 | C35: 269251.4 | D35: 43433 | E35: 0 | F35: AB | G35: 45918 | Q35: ABC
A36: Materfer - U. | B36: 3509 | C36: 430868.9 | D36: 43805 | E36: 0 | F36: A | G36: 45916 | H36: ABC+BV
A37: Materfer - U. | B37: 3524 | C37: - Detenido en Reparación General desde fecha 22/04/25 -
A38: Materfer - U. | B38: 3529 | C38: 121290.7 | D38: 44347 | E38: 5846 | F38: ABC | G38: 45678
A39: Materfer - U. | B39: 3534 | C39: 643799.6 | D39: 41560 | E39: 0 | F39: ABC | G39: 45876 | M39: ABC+BV
A40: Materfer - U. | B40: 3545 | C40: 667599.8 | D40: 42674 | E40: 11250.2 | F40: A | G40: 45824 | R40: ABC+BV
A41: Materfer - U. | B41: 3547 | C41: 247353.8 | D41: 42811 | E41: 1805 | F41: RP | G41: 45901
A42: Materfer - U. | B42: 3558 | C42: 650991.1 | D42: 41439 | E42: 6498 | F42: ABC | G42: 45744 | N42: ABC+BV
...

Sheet LGR RESUMEN CCRR
G1: Planilla Tipo: MRAM (2)
G3: Avance de Mantenimiento Preventivo
F5: AVANCE DE TAREAS REALIZADAS AL MES DE: | L5: (a)___________________
I6: TIPO DE VEHÍCULO: | L6: Coche Remolcado
C8: CANTIDAD DE INTERVENCIONES
A10: Tipo de Revisión | B10: Período | C10: ENERO | E10: FEBRERO | G10: MARZO | I10: ABRIL | K10: MAYO | M10: JUNIO | O10: JULIO | Q10: AGOSTO | S10: SEPTIEMBRE | U10: OCTUBRE | W10: NOVIEMBRE | Y10: DICIEMBRE | AA10: TOTAL
C11: Prog. | D11: Realiz. | E11: Prog. | F11: Realiz. | G11: Prog. | H11: Realiz. | I11: Prog. | J11: Realiz. | K11: Prog. | L11: Realiz. | M11: Prog. | N11: Realiz. | O11: Prog. | P11: Realiz. | Q11: Prog. | R11: Realiz. | S11: Prog. | T11: Realiz. | U11: Prog. | V11: Realiz. | W11: Prog. | X11: Realiz. | Y11: Prog. | Z11: Realiz. | AA11: Prog. | AB11: Realiz.
A12: Revisión A | B12: 15.000 Km. | C12: 10 | E12: 9 | G12: 10 | I12: 9 | K12: 10 | M12: 9 | O12: 10 | Q12: 10 | S12: 9 | U12: 10 | W12: 9 | Y12: 10 | AA12: =SUM(C12+E12+G12+I12+K12+M12+O12+Q12+S12+U12+W12+Y12) -> 115 | AB12: =+D12+F12+H12+J12+L12+N12+P12+R12+T12+V12+X12+Z12 -> 0
A13: Revisión AB | B13: 30.000 Km. | C13: 6 | E13: 5 | G13: 6 | I13: 6 | K13: 6 | M13: 5 | O13: 6 | Q13: 6 | S13: 6 | U13: 6 | W13: 6 | Y13: 6 | AA13: =SUM(C13+E13+G13+I13+K13+M13+O13+Q13+S13+U13+W13+Y13) -> 70 | AB13: =+D13+F13+H13+J13+L13+N13+P13+R13+T13+V13+X13+Z13 -> 0
A14: Revisión ABC | B14: 120.000 Km. | C14: 7 | E14: 3 | G14: 2 | I14: 0 | K14: 4 | M14: 3 | O14: 5 | Q14: 2 | S14: 1 | U14: 5 | W14: 8 | Y14: 7 | AA14: =SUM(C14+E14+G14+I14+K14+M14+O14+Q14+S14+U14+W14+Y14) -> 47 | AB14: =+D14+F14+H14+J14+L14+N14+P14+R14+T14+V14+X14+Z14 -> 0
A15: Reparación Parcial | B15: 240.000 Km. | C15: 0 | E15: 0 | G15: 0 | I15: 0 | K15: 0 | M15: 0 | O15: 0 | Q15: 0 | S15: 0 | U15: 0 | W15: 0 | Y15: 0 | AA15: =SUM(C15+E15+G15+I15+K15+M15+O15+Q15+S15+U15+W15+Y15) -> 0 | AB15: =+D15+F15+H15+J15+L15+N15+P15+R15+T15+V15+X15+Z15 -> 0
A16: Reparación General | B16: 480.000 Km. | C16: 1 | E16: 0 | G16: 1 | I16: 0 | K16: 0 | M16: 0 | O16: 0 | Q16: 0 | S16: 0 | U16: 0 | W16: 0 | Y16: 0 | AA16: =SUM(C16+E16+G16+I16+K16+M16+O16+Q16+S16+U16+W16+Y16) -> 2 | AB16: =+D16+F16+H16+J16+L16+N16+P16+R16+T16+V16+X16+Z16 -> 0

Sheet LGR LOCS CNR
G1: Planilla Tipo: MRMPA
G3: ='LGR CCEE'!G3:K3 -> Plan de Mantenimiento Preventivo Año: 2026
G4: Kilometraje anual previsto a recorrer: 775.709
E5: MES de: | G5: (a)___________________
E6: TIPO DE VEHÍCULO: | G6: Locomotora CNR
A8: ='LGR CCRR'!A8 -> Km. al: 30/09/2025 | C8: Última R.G. | E8: Última Revisión | H8: ='LGR CCRR'!H8:S8 -> AÑO 2026
A9: Marca-Modelo | B9: Número | C9: Km. | D9: Fecha | E9: Km. | F9: Tipo | G9: Fecha | H9: ENE. | I9: FEB. | J9: MAR. | K9: ABR. | L9: MAY. | M9: JUN. | N9: JUL. | O9: AGO. | P9: SEP. | Q9: OCT. | R9: NOV. | S9: DIC.
A10: CNR CKD 8G | B10: 0001 | C10: 673487 | D10: 41653 | E10: 10301 | F10: EX | G10: 45897 | K10: R6
A11: CNR CKD 8G | B11: 0005 | C11: 697777 | D11: 41723 | E11: 4662 | F11: EX | G11: 45919 | O11: N
A12: CNR CKD 8G | B12: 0006 | C12: 540109 | D12: 41653 | E12: 2283 | F12: N | G12: 45912
A13: CNR CKD 8G | B13: 0008 | C13: 378295 | D13: 40909 | E13: - | F13: - | G13: - | L13: N
A14: CNR CKD 8G | B14: 0009 | C14: 834351 | D14: 41857 | E14: 5738 | F14: EX | G14: 45890 | N14: N
A15: CNR CKD 8G | B15: 0012 | C15: 781802 | D15: 41859 | E15: 3660 | F15: R3 | G15: 45919 | I15: N
A16: CNR CKD 8G | B16: 0013 | C16: 718609 | D16: 41859 | E16: 3572 | F16: EX | G16: 45813 | R16: N
F18: 8 | G18: EX | H18: =COUNTIF(H10:H16,"EX") -> 0 | I18: =COUNTIF(I10:I16,"EX") -> 0 | J18: =COUNTIF(J10:J16,"EX") -> 0 | K18: =COUNTIF(K10:K16,"EX") -> 0 | L18: =COUNTIF(L10:L16,"EX") -> 0 | M18: =COUNTIF(M10:M16,"EX") -> 0 | N18: =COUNTIF(N10:N16,"EX") -> 0 | O18: =COUNTIF(O10:O16,"EX") -> 0 | ... S18: =COUNTIF(S10:S16,"EX") -> 0 | T18: =SUM(H18:S18) -> 0
F19: 7 | G19: R1 | H19: =COUNTIF(H10:H16,"R1") -> 0 | I19: =COUNTIF(I10:I16,"R1") -> 0 | J19: =COUNTIF(J10:J16,"R1") -> 0 | K19: =COUNTIF(K10:K16,"R1") -> 0 | L19: =COUNTIF(L10:L16,"R1") -> 0 | M19: =COUNTIF(M10:M16,"R1") -> 0 | N19: =COUNTIF(N10:N16,"R1") -> 0 | O19: =COUNTIF(O10:O16,"R1") -> 0 | ... S19: =COUNTIF(S10:S16,"R1") -> 0 | T19: =SUM(H19:S19) -> 0
F20: 6 | G20: R2 | H20: =COUNTIF(H10:H16,"R2") -> 0 | I20: =COUNTIF(I10:I16,"R2") -> 0 | J20: =COUNTIF(J10:J16,"R2") -> 0 | K20: =COUNTIF(K10:K16,"R2") -> 0 | L20: =COUNTIF(L10:L16,"R2") -> 0 | M20: =COUNTIF(M10:M16,"R2") -> 0 | N20: =COUNTIF(N10:N16,"R2") -> 0 | O20: =COUNTIF(O10:O16,"R2") -> 0 | ... S20: =COUNTIF(S10:S16,"R2") -> 0 | T20: =SUM(H20:S20) -> 0
F21: 5 | G21: R3 | H21: =COUNTIF(H10:H16,"R3") -> 0 | I21: =COUNTIF(I10:I16,"R3") -> 0 | J21: =COUNTIF(J10:J16,"R3") -> 0 | K21: =COUNTIF(K10:K16,"R3") -> 0 | L21: =COUNTIF(L10:L16,"R3") -> 0 | M21: =COUNTIF(M10:M16,"R3") -> 0 | N21: =COUNTIF(N10:N16,"R3") -> 0 | O21: =COUNTIF(O10:O16,"R3") -> 0 | ... S21: =COUNTIF(S10:S16,"R3") -> 0 | T21: =SUM(H21:S21) -> 0
F22: 4 | G22: R4 | H22: =COUNTIF(H10:H16,"R4") -> 0 | I22: =COUNTIF(I10:I16,"R4") -> 0 | J22: =COUNTIF(J10:J16,"R4") -> 0 | K22: =COUNTIF(K10:K16,"R4") -> 0 | L22: =COUNTIF(L10:L16,"R4") -> 0 | M22: =COUNTIF(M10:M16,"R4") -> 0 | N22: =COUNTIF(N10:N16,"R4") -> 0 | O22: =COUNTIF(O10:O16,"R4") -> 0 | ... S22: =COUNTIF(S10:S16,"R4") -> 0 | T22: =SUM(H22:S22) -> 0
F23: 3 | G23: R5 | H23: =COUNTIF(H10:H16,"R5") -> 0 | I23: =COUNTIF(I10:I16,"R5") -> 0 | J23: =COUNTIF(J10:J16,"R5") -> 0 | K23: =COUNTIF(K10:K16,"R5") -> 0 | L23: =COUNTIF(L10:L16,"R5") -> 0 | M23: =COUNTIF(M10:M16,"R5") -> 0 | N23: =COUNTIF(N10:N16,"R5") -> 0 | O23: =COUNTIF(O10:O16,"R5") -> 0 | ... S23: =COUNTIF(S10:S16,"R5") -> 0 | T23: =SUM(H23:S23) -> 0
F24: 2 | G24: R6 | H24: =COUNTIF(H10:H16,"R6") -> 0 | I24: =COUNTIF(I10:I16,"R6") -> 0 | J24: =COUNTIF(J10:J16,"R6") -> 0 | K24: =COUNTIF(K10:K16,"R6") -> 1 | L24: =COUNTIF(L10:L16,"R6") -> 0 | M24: =COUNTIF(M10:M16,"R6") -> 0 | N24: =COUNTIF(N10:N16,"R6") -> 0 | O24: =COUNTIF(O10:O16,"R6") -> 0 | ... S24: =COUNTIF(S10:S16,"R6") -> 0 | T24: =SUM(H24:S24) -> 1
G25: N | H25: =COUNTIF(H10:H16,"N") -> 0 | I25: =COUNTIF(I10:I16,"N") -> 1 | J25: =COUNTIF(J10:J16,"N") -> 0 | K25: =COUNTIF(K10:K16,"N") -> 0 | L25: =COUNTIF(L10:L16,"N") -> 1 | M25: =COUNTIF(M10:M16,"N") -> 0 | N25: =COUNTIF(N10:N16,"N") -> 1 | O25: =COUNTIF(O10:O16,"N") -> 1 | ... S25: =COUNTIF(S10:S16,"N") -> 0 | T25: =SUM(H25:S25) -> 5
A26: (*) | B26: unidad fuera de servicio

Sheet LGR RESUMEN LOCS CNR
G1: Planilla Tipo: MRAM (2)
G3: Avance de Mantenimiento Preventivo
F5: AVANCE DE TAREAS REALIZADAS AL MES DE: | L5: (a)___________________
I6: TIPO DE VEHÍCULO: | L6: Locomotora CNR
C8: CANTIDAD DE INTERVENCIONES
A10: Tipo de Revisión | B10: Período | C10: ENERO | E10: FEBRERO | G10: MARZO | I10: ABRIL | K10: MAYO | M10: JUNIO | O10: JULIO | Q10: AGOSTO | S10: SEPTIEMBRE | U10: OCTUBRE | W10: NOVIEMBRE | Y10: DICIEMBRE | AA10: TOTAL
C11: Prog. | D11: Realiz. | E11: Prog. | F11: Realiz. | G11: Prog. | H11: Realiz. | I11: Prog. | J11: Realiz. | K11: Prog. | L11: Realiz. | M11: Prog. | N11: Realiz. | O11: Prog. | P11: Realiz. | Q11: Prog. | R11: Realiz. | S11: Prog. | T11: Realiz. | U11: Prog. | V11: Realiz. | W11: Prog. | X11: Realiz. | Y11: Prog. | Z11: Realiz. | AA11: Prog. | AB11: Realiz.
A12: Examen | B12: 10.000 Km. | C12: 3 | E12: 4 | G12: 4 | I12: 4 | K12: 4 | M12: 5 | O12: 4 | Q12: 3 | S12: 6 | U12: 4 | W12: 4 | Y12: 6 | AA12: =SUM(C12+E12+G12+I12+K12+M12+O12+Q12+S12+U12+W12+Y12) -> 51 | AB12: =+D12+F12+H12+J12+L12+N12+P12+R12+T12+V12+X12+Z12 -> 0
A13: Revisión 1 | B13: 20.000 Km. | C13: 1 | E13: 1 | G13: 0 | I13: 1 | K13: 1 | M13: 0 | O13: 1 | Q13: 1 | S13: 0 | U13: 0 | W13: 1 | Y13: 0 | AA13: =SUM(C13+E13+G13+I13+K13+M13+O13+Q13+S13+U13+W13+Y13) -> 7 | AB13: =+D13+F13+H13+J13+L13+N13+P13+R13+T13+V13+X13+Z13 -> 0
A14: Revisión 2 | B14: 40.000 Km. | C14: 0 | E14: 1 | G14: 1 | I14: 0 | K14: 1 | M14: 1 | O14: 1 | Q14: 1 | S14: 0 | U14: 1 | W14: 1 | Y14: 0 | AA14: =SUM(C14+E14+G14+I14+K14+M14+O14+Q14+S14+U14+W14+Y14) -> 8 | AB14: =+D14+F14+H14+J14+L14+N14+P14+R14+T14+V14+X14+Z14 -> 0
A15: Revisión 3 | B15: 60.000 Km. | C15: 1 | E15: 0 | G15: 0 | I15: 0 | K15: 1 | M15: 1 | O15: 0 | Q15: 1 | S15: 0 | U15: 2 | W15: 0 | Y15: 0 | AA15: =SUM(C15+E15+G15+I15+K15+M15+O15+Q15+S15+U15+W15+Y15) -> 6 | AB15: =+D15+F15+H15+J15+L15+N15+P15+R15+T15+V15+X15+Z15 -> 0
A16: Revisión 4 | B16: 80.000 Km. | C16: 0 | E16: 0 | G16: 0 | I16: 0 | K16: 0 | M16: 0 | O16: 0 | Q16: 0 | S16: 1 | U16: 0 | W16: 0 | Y16: 0 | AA16: =SUM(C16+E16+G16+I16+K16+M16+O16+Q16+S16+U16+W16+Y16) -> 1 | AB16: =+D16+F16+H16+J16+L16+N16+P16+R16+T16+V16+X16+Z16 -> 0
A17: Revisión 5 | B17: 100.000 Km. | C17: 0 | E17: 0 | G17: 0 | I17: 0 | K17: 0 | M17: 0 | O17: 0 | Q17: 0 | S17: 0 | U17: 0 | W17: 0 | Y17: 1 | AA17: =SUM(C17+E17+G17+I17+K17+M17+O17+Q17+S17+U17+W17+Y17) -> 1 | AB17: =+D17+F17+H17+J17+L17+N17+P17+R17+T17+V17+X17+Z17 -> 0
A18: Revisión 6 | B18: 120.000 Km. | C18: 0 | E18: 0 | G18: 0 | I18: 1 | K18: 0 | M18: 0 | O18: 0 | Q18: 0 | S18: 0 | U18: 0 | W18: 0 | Y18: 0 | AA18: =SUM(C18+E18+G18+I18+K18+M18+O18+Q18+S18+U18+W18+Y18) -> 1 | AB18: =+D18+F18+H18+J18+L18+N18+P18+R18+T18+V18+X18+Z18 -> 0
A19: Reparación Numeral "1" | B19: 360.000 Km. | C19: 0 | E19: 1 | G19: 0 | I19: 0 | K19: 1 | M19: 0 | O19: 1 | Q19: 1 | S19: 0 | U19: 0 | W19: 1 | Y19: 0 | AA19: =SUM(C19+E19+G19+I19+K19+M19+O19+Q19+S19+U19+W19+Y19) -> 5 | AB19: =+D19+F19+H19+J19+L19+N19+P19+R19+T19+V19+X19+Z19 -> 0
A20: Reparación Numeral "2" | B20: 720.000 Km. | C20: 0 | E20: 0 | G20: 0 | I20: 0 | K20: 0 | M20: 0 | O20: 0 | Q20: 0 | S20: 0 | U20: 0 | W20: 0 | Y20: 0 | AA20: =SUM(C20+E20+G20+I20+K20+M20+O20+Q20+S20+U20+W20+Y20) -> 0 | AB20: =+D20+F20+H20+J20+L20+N20+P20+R20+T20+V20+X20+Z20 -> 0

Sheet LGR CCRR CNR
G1: Planilla Tipo: MRMPA
G3: ='LGR CCEE'!G3:K3 -> Plan de Mantenimiento Preventivo Año: 2026
G4: Kilometraje anual previsto a recorrer: 9.348.504
E5: MES de: | G5: (a)___________________
E6: TIPO DE VEHÍCULO: | G6: Coche Remolcado CNR
A8: ='LGR LOCS CNR'!A8 -> Km. al: 30/09/2025 | C8: Última R.G. | E8: Última Revisión | H8: ='LGR LOCS CNR'!H8:S8 -> AÑO 2026
A9: Marca-Modelo | B9: Número | C9: Km. | D9: Fecha | E9: Km. | F9: Tipo | G9: Fecha | H9: ENE. | I9: FEB. | J9: MAR. | K9: ABR. | L9: MAY. | M9: JUN. | N9: JUL. | O9: AGO. | P9: SEP. | Q9: OCT. | R9: NOV. | S9: DIC.
A10: CNR | B10: CDA004 | C10: 238877 | D10: 41898 | E10: 55622 | F10: MEN | G10: 45318
A11: CNR | B11: CDA006 | C11: 546265 | D11: 41624 | E11: 0 | F11: MEN | G11: 45335
A12: CNR | B12: CPA002 | C12: 778280 | D12: 41653 | E12: 8319 | F12: MEN | G12: 45885 | O12: A3
A13: CNR | B13: CPA003 | C13: 804522 | D13: 41653 | E13: 6675 | F13: MEN | G13: 45899 | I13: A3
A14: CNR | B14: CPA005 | C14: 814258 | D14: 41653 | E14: 9163 | F14: MEN | G14: 45864 | K14: A3
A15: CNR | B15: CPA006 | C15: 660899 | D15: 41653 | E15: 7508 | F15: MEN | G15: 45892 | S15: A1
A16: CNR | B16: CPA013 | C16: 725551 | D16: 41954 | E16: 411 | F16: SEM | G16: 45927 | L16: A3
A17: CNR | B17: CPA014 | C17: 457136 | D17: 41911 | E17: 411 | F17: SEM | G17: 45808
A18: CNR | B18: CPA018 | C18: 575035 | D18: 42058 | E18: 9963 | F18: MEN | G18: 44975
A19: CNR | B19: CPA019 | C19: 667396 | D19: 41954 | E19: 5009 | F19: MEN | G19: 45906
A20: CNR | B20: CPA020 | C20: 668481 | D20: 41911 | E20: 1666 | F20: SEM | G20: 45919
A21: CNR | B21: CPA025 | C21: 819482 | D21: 41617 | E21: 5009 | F21: MEN | G21: 45906
A22: CNR | B22: CPA026 | C22: 728922 | D22: 41617 | E22: 7508 | F22: SEM | G22: 45884 | M22: A3
A23: CNR | B23: CPA027 | C23: 905755 | D23: 41617 | E23: 0 | F23: MEN | G23: 45801 | R23: A1
A24: CNR | B24: CPA031 | C24: 765324 | D24: 41744 | E24: 411 | F24: A1 | G24: 45912 | R24: A3
A25: CNR | B25: CPA033 | C25: 751199 | D25: 41835 | E25: 11651 | F25: SEM | G25: 45864 | P25: A1
A26: CNR | B26: CPA034 | C26: 762598 | D26: 41835 | E26: 8319 | F26: MEN | G26: 45885 | R26: A3
A27: CNR | B27: CPA035 | C27: 764553 | D27: 41744 | E27: 0 | F27: A1 | G27: 45926 | S27: A3
A28: CNR | B28: CPA037 | C28: 593229 | D28: 41704 | E28: 0 | F28: SEM | G28: 45919 | O28: A1
A29: CNR | B29: CPA039 | C29: 716553 | D29: 41704 | E29: 6675 | F29: SEM | G29: 45899 | K29: A1
A30: CNR | B30: CPA041 | C30: 659108 | D30: 41704 | E30: 7508 | F30: SEM | G30: 45777
A31: CNR | B31: CPA042 | C31: 644665 | D31: 41704 | E31: 4165 | F31: SEM | G31: 45773 | N31: A1
A32: CNR | B32: CPA044 | C32: 568764 | D32: 41704 | E32: 0 | F32: SEM | G32: 45567
A33: CNR | B33: CPA045 | C33: 606914 | D33: 41704 | E33: 8319 | F33: MEN | G33: 45885
A34: CNR | B34: CPA046 | C34: 758356 | D34: 41911 | E34: 1666 | F34: A1 | G34: 45859
A35: CNR | B35: CPA058 | C35: 640735 | D35: 41835 | E35: 411 | F35: MEN | G35: 45892 | R35: A1
A36: CNR | B36: CPA060 | C36: 777933 | D36: 41744 | E36: 3332 | F36: SEM | G36: 45913 | R36: A1
A37: CNR | B37: CPA063 | C37: 742719 | D37: 41835 | E37: 1666 | F37: MEN | G37: 45919
A38: CNR | B38: CPA064 | C38: 645425 | D38: 41835 | E38: 0 | F38: MEN | G38: 45826 | J38: A1
A39: CNR | B39: CPA068 | C39: 740240 | D39: 41954 | E39: 6675 | F39: MEN | G39: 45899
A40: CNR | B40: CPA070 | C40: 758314 | D40: 41911 | E40: 0 | F40: A1 | G40: 45833
A41: CNR | B41: CPA072 | C41: 555520 | D41: 41911 | E41: 0 | F41: SEM | G41: 45567 | M41: A1
A42: CNR | B42: CPA073 | C42: 729156 | D42: 41806 | E42: 1666 | F42: SEM | G42: 45919
...

Sheet LGR RESUMEN CCRR CNR
G1: Planilla Tipo: MRAM (2)
G3: Avance de Mantenimiento Preventivo
F5: AVANCE DE TAREAS REALIZADAS AL MES DE: | L5: (a)___________________
I6: TIPO DE VEHÍCULO: | L6: Coche Remolcado CNR
C8: CANTIDAD DE INTERVENCIONES
A10: Tipo de Revisión | B10: Período | C10: ENERO | E10: FEBRERO | G10: MARZO | I10: ABRIL | K10: MAYO | M10: JUNIO | O10: JULIO | Q10: AGOSTO | S10: SEPTIEMBRE | U10: OCTUBRE | W10: NOVIEMBRE | Y10: DICIEMBRE | AA10: TOTAL
C11: Prog. | D11: Realiz. | E11: Prog. | F11: Realiz. | G11: Prog. | H11: Realiz. | I11: Prog. | J11: Realiz. | K11: Prog. | L11: Realiz. | M11: Prog. | N11: Realiz. | O11: Prog. | P11: Realiz. | Q11: Prog. | R11: Realiz. | S11: Prog. | T11: Realiz. | U11: Prog. | V11: Realiz. | W11: Prog. | X11: Realiz. | Y11: Prog. | Z11: Realiz. | AA11: Prog. | AB11: Realiz.
A12: Revisión Mensual | B12: 1 mes | C12: 30 | E12: 30 | G12: 30 | I12: 30 | K12: 30 | M12: 30 | O12: 30 | Q12: 30 | S12: 30 | U12: 30 | W12: 30 | Y12: 30 | AA12: =SUM(C12+E12+G12+I12+K12+M12+O12+Q12+S12+U12+W12+Y12) -> 360 | AB12: =+D12+F12+H12+J12+L12+N12+P12+R12+T12+V12+X12+Z12 -> 0
A13: Revisión Semestral | B13: 6 meses | C13: 15 | E13: 15 | G13: 15 | I13: 15 | K13: 15 | M13: 15 | O13: 15 | Q13: 15 | S13: 15 | U13: 15 | W13: 15 | Y13: 15 | AA13: =SUM(C13+E13+G13+I13+K13+M13+O13+Q13+S13+U13+W13+Y13) -> 180 | AB13: =+D13+F13+H13+J13+L13+N13+P13+R13+T13+V13+X13+Z13 -> 0
A14: Revisión A1 | B14: 200.000 Km. | C14: 3 | E14: 3 | G14: 2 | I14: 2 | K14: 2 | M14: 3 | O14: 1 | Q14: 2 | S14: 4 | U14: 5 | W14: 5 | Y14: 4 | AA14: =SUM(C14+E14+G14+I14+K14+M14+O14+Q14+S14+U14+W14+Y14) -> 36 | AB14: =+D14+F14+H14+J14+L14+N14+P14+R14+T14+V14+X14+Z14 -> 0
A15: Reparación A2 | B15: 400.000 Km. | C15: 0 | E15: 0 | G15: 0 | I15: 0 | K15: 0 | M15: 0 | O15: 0 | Q15: 0 | S15: 0 | U15: 0 | W15: 0 | Y15: 0 | AA15: =SUM(C15+E15+G15+I15+K15+M15+O15+Q15+S15+U15+W15+Y15) -> 0 | AB15: =+D15+F15+H15+J15+L15+N15+P15+R15+T15+V15+X15+Z15 -> 0
A16: Reparación A3 | B16: 800.000 Km. | C16: 1 | E16: 1 | G16: 1 | I16: 2 | K16: 2 | M16: 2 | O16: 2 | Q16: 2 | S16: 2 | U16: 3 | W16: 2 | Y16: 1 | AA16: =SUM(C16+E16+G16+I16+K16+M16+O16+Q16+S16+U16+W16+Y16) -> 21 | AB16: =+D16+F16+H16+J16+L16+N16+P16+R16+T16+V16+X16+Z16 -> 0
B18: A1 + BV | C18: 0 | E18: 0 | G18: 0 | I18: 0 | K18: 0 | M18: 0 | O18: 0 | Q18: 0 | S18: 0 | U18: 0 | W18: 0 | Y18: 0
B19: A1 | C19: 1 | E19: 3 | G19: 3 | I19: 3 | K19: 2 | M19: 1 | O19: 3 | Q19: 1 | S19: 5 | U19: 1 | W19: 1 | Y19: 4
B20: A2 | C20: 2 | E20: 2 | G20: 2 | I20: 3 | K20: 0 | M20: 0 | O20: 0 | Q20: 3 | S20: 1 | U20: 0 | W20: 2 | Y20: 2
B21: A3 | C21: 0 | E21: 0 | G21: 0 | I21: 1 | K21: 1 | M21: 1 | O21: 1 | Q21: 0 | S21: 0 | U21: 0 | W21: 0 | Y21: 0

Sheet LGR CCMM NOHAB
G1: Planilla Tipo: MRMPA
G3: ='LGR CCEE'!G3:K3 -> Plan de Mantenimiento Preventivo Año: 2026
G4: Kilometraje anual previsto a recorrer: 45.245
E5: MES de: | G5: (a)___________________
E6: TIPO DE VEHÍCULO: | G6: Coche Motor
B7: Km Mes: | C7: 1700
A8: ='LGR CCRR CNR'!A8 -> Km. al: 30/09/2025 | C8: Última R.G. | E8: Última Revisión | H8: ='LGR CCRR CNR'!H8:S8 -> AÑO 2026
A9: Marca-Modelo | B9: Número | C9: Km. | D9: Fecha | E9: Km. | F9: Tipo | G9: Fecha | H9: ENE. | I9: FEB. | J9: MAR. | K9: ABR. | L9: MAY. | M9: JUN. | N9: JUL. | O9: AGO. | P9: SEP. | Q9: OCT. | R9: NOV. | S9: DIC.
A10: NOHAB - 0100 | B10: 105 | C10: 252631 | D10: 39136 | E10: 4014 | F10: SEM | G10: 45889 | U10: MEN
A11: NOHAB - 0100 | B11: 106 | C11: 271746.1 | D11: 39136 | E11: 0 | F11: MEN | G11: 45930 | T11: MEN | V11: SEM
G13: MEN | H13: =COUNTIF(H10:H11,"MEN") -> 0 | I13: =COUNTIF(I10:I11,"MEN") -> 0 | J13: =COUNTIF(J10:J11,"MEN") -> 0 | K13: =COUNTIF(K10:K11,"MEN") -> 0 | L13: =COUNTIF(L10:L11,"MEN") -> 0 | M13: =COUNTIF(M10:M11,"MEN") -> 0 | N13: =COUNTIF(N10:N11,"MEN") -> 0 | O13: =COUNTIF(O10:O11,"MEN") -> 0 | ... S13: =COUNTIF(S10:S11,"MEN") -> 0 | T13: =SUM(H13:S13) -> 0
A14: Mensual | B14: 4.000 Km. | G14: SEM | H14: =COUNTIF(H10:H11,"SEM") -> 0 | I14: =COUNTIF(I10:I11,"SEM") -> 0 | J14: =COUNTIF(J10:J11,"SEM") -> 0 | K14: =COUNTIF(K10:K11,"SEM") -> 0 | L14: =COUNTIF(L10:L11,"SEM") -> 0 | M14: =COUNTIF(M10:M11,"SEM") -> 0 | N14: =COUNTIF(N10:N11,"SEM") -> 0 | O14: =COUNTIF(O10:O11,"SEM") -> 0 | ... S14: =COUNTIF(S10:S11,"SEM") -> 0 | T14: =SUM(H14:S14) -> 0
A15: Semestral | B15: 24.000Km. | G15: RP | H15: =COUNTIF(H10:H11,"RP") -> 0 | I15: =COUNTIF(I10:I11,"RP") -> 0 | J15: =COUNTIF(J10:J11,"RP") -> 0 | K15: =COUNTIF(K10:K11,"RP") -> 0 | L15: =COUNTIF(L10:L11,"RP") -> 0 | M15: =COUNTIF(M10:M11,"RP") -> 0 | N15: =COUNTIF(N10:N11,"RP") -> 0 | O15: =COUNTIF(O10:O11,"RP") -> 0 | ... S15: =COUNTIF(S10:S11,"RP") -> 0 | T15: =SUM(H15:S15) -> 0

Sheet LGR RESUMEN CCMM NOHAB
G1: Planilla Tipo: MRAM (2)
G3: Avance de Mantenimiento Preventivo
F5: AVANCE DE TAREAS REALIZADAS AL MES DE: | L5: (a)___________________
I6: TIPO DE VEHÍCULO: | L6: Coche Motor Nohab
C8: CANTIDAD DE INTERVENCIONES
A10: Tipo de Revisión | B10: Período | C10: ENERO | E10: FEBRERO | G10: MARZO | I10: ABRIL | K10: MAYO | M10: JUNIO | O10: JULIO | Q10: AGOSTO | S10: SEPTIEMBRE | U10: OCTUBRE | W10: NOVIEMBRE | Y10: DICIEMBRE | AA10: TOTAL
C11: Prog. | D11: Realiz. | E11: Prog. | F11: Realiz. | G11: Prog. | H11: Realiz. | I11: Prog. | J11: Realiz. | K11: Prog. | L11: Realiz. | M11: Prog. | N11: Realiz. | O11: Prog. | P11: Realiz. | Q11: Prog. | R11: Realiz. | S11: Prog. | T11: Realiz. | U11: Prog. | V11: Realiz. | W11: Prog. | X11: Realiz. | Y11: Prog. | Z11: Realiz. | AA11: Prog. | AB11: Realiz.
A12: Revisión Mensual | B12: 4.000 Km. | C12: 0 | E12: 1 | G12: 0 | I12: 0 | K12: 1 | M12: 0 | O12: 1 | Q12: 1 | S12: 0 | U12: 1 | W12: 1 | Y12: 0 | AA12: =SUM(C12+E12+G12+I12+K12+M12+O12+Q12+S12+U12+W12+Y12) -> 6 | AB12: =+D12+F12+H12+J12+L12+N12+P12+R12+T12+V12+X12+Z12 -> 0
A13: Revisión Semestral | B13: 24.000Km. | C13: 0 | E13: 0 | G13: 1 | I13: 0 | K13: 0 | M13: 1 | O13: 0 | Q13: 0 | S13: 1 | U13: 0 | W13: 0 | Y13: 1 | AA13: =SUM(C13+E13+G13+I13+K13+M13+O13+Q13+S13+U13+W13+Y13) -> 4 | AB13: =+D13+F13+H13+J13+L13+N13+P13+R13+T13+V13+X13+Z13 -> 0
A14: Reparación Parcial | B14: 240.000Km. | C14: 0 | E14: 0 | G14: 0 | I14: 0 | K14: 0 | M14: 0 | O14: 0 | Q14: 0 | S14: 0 | U14: 0 | W14: 0 | Y14: 0 | AA14: =SUM(C14+E14+G14+I14+K14+M14+O14+Q14+S14+U14+W14+Y14) -> 0 | AB14: =+D14+F14+H14+J14+L14+N14+P14+R14+T14+V14+X14+Z14 -> 0

Sheet LGR VAGONES
G1: Planilla Tipo: MRAM (1)
G3: ='LGR CCEE'!G3:K3 -> Plan de Mantenimiento Preventivo Año: 2026
G4: Kilometraje anual previsto a recorrer: -
E6: TIPO DE VEHÍCULO: | G6: Vagón
A7: Km Mes:
A8: ='LGR CCMM NOHAB'!A8:B8 -> Km. al: 30/09/2025 | C8: Última R.G. | E8: Última Revisión | H8: ='LGR CCMM NOHAB'!H8:S8 -> AÑO 2026
A9: Marca-Modelo | B9: Número | C9: Km. | D9: Fecha | E9: Km. | F9: Tipo | G9: Fecha | H9: ENE. | I9: FEB. | J9: MAR. | K9: ABR. | L9: MAY. | M9: JUN. | N9: JUL. | O9: AGO. | P9: SEP. | Q9: OCT. | R9: NOV. | S9: DIC.
A10: Vagón cerrado | B10: 455881 | D10: - | E10: - | F10: AL | G10: 45804 | L10: REV
A11: Vagón cerrado | B11: 456251 | D11: - | E11: - | F11: AL | G11: 45896 | J11: B
A12: Vagón plataforma | B12: 529107 | D12: - | E12: - | F12: AL | G12: 45904 | K12: B
A13: Vagón plataforma | B13: 792499 | D13: - | E13: - | F13: A | G13: 45896
A14: Vagón plataforma | B14: 947192 | D14: - | E14: - | F14: B | G14: 45635 | P14: AL
A15: Vagón plataforma | B15: 947325 | D15: - | E15: - | F15: REV | G15: 45635 | P15: AL
A16: Vagón plataforma | B16: 947366 | D16: - | E16: - | F16: REV | G16: 45750 | S16: AL
A17: Vagón plataforma | B17: 947457 | D17: - | E17: - | F17: REV | G17: 45669 | S17: AL
A18: Vagón Tolva (Hopper) | B18: 977942 | D18: - | E18: - | F18: AL | G18: 45669 | K18: AL
A19: Vagón Tolva (Hopper) | B19: 978163 | D19: - | E19: - | F19: AL | G19: 45642
A20: Vagón Tolva (Hopper) | B20: 979088 | D20: - | E20: - | F20: AL | G20: 45324
A21: Vagón Tolva (Hopper) | B21: 979799 | D21: - | E21: - | F21: REV | G21: 45768
A22: Vagón Tolva (Hopper) | B22: 980300 | D22: - | E22: - | F22: AL | G22: 45771 | Q22: AL
A23: Vagón Tolva (Hopper) | B23: 980995 | D23: - | E23: - | F23: AL | G23: 45859 | Q23: AL
A24: Vagón Tolva (Hopper) | B24: 981456 | D24: - | E24: - | F24: AL | G24: 45616 | I24: AL
A25: Vagón Tolva (Hopper) | B25: 981670 | D25: - | E25: - | F25: AL | G25: 45415 | K25: AL
A26: Vagón Tolva (Hopper) | B26: 981787 | D26: - | E26: - | F26: AL | G26: 45583
A27: Vagón plataforma | B27: M21 | D27: - | E27: - | F27: REV | G27: 45540 | H27: B
A28: Vagón plataforma | B28: M22 | D28: - | E28: - | F28: REV | G28: 45532 | I28: B
G32: Alistamiento | H32: =COUNTIF(H10:H30,"AL") -> 0 | I32: =COUNTIF(I10:I30,"AL") -> 1 | J32: =COUNTIF(J10:J30,"AL") -> 0 | K32: =COUNTIF(K10:K30,"AL") -> 2 | L32: =COUNTIF(L10:L30,"AL") -> 0 | M32: =COUNTIF(M10:M30,"AL") -> 0 | N32: =COUNTIF(N10:N30,"AL") -> 0 | O32: =COUNTIF(O10:O30,"AL") -> 0 | ... S32: =COUNTIF(S10:S30,"AL") -> 2 | T32: =SUM(H32:S32) -> 9
G33: REV | H33: =COUNTIF(H10:H30,"REV") -> 0 | I33: =COUNTIF(I10:I30,"REV") -> 0 | J33: =COUNTIF(J10:J30,"REV") -> 0 | K33: =COUNTIF(K10:K30,"REV") -> 0 | L33: =COUNTIF(L10:L30,"REV") -> 1 | M33: =COUNTIF(M10:M30,"REV") -> 0 | N33: =COUNTIF(N10:N30,"REV") -> 0 | O33: =COUNTIF(O10:O30,"REV") -> 0 | ... S33: =COUNTIF(S10:S30,"REV") -> 0 | T33: =SUM(H33:S33) -> 1
G34: Revision A | H34: =COUNTIF(H10:H30,"A") -> 0 | I34: =COUNTIF(I10:I30,"A") -> 0 | J34: =COUNTIF(J10:J30,"A") -> 0 | K34: =COUNTIF(K10:K30,"A") -> 0 | L34: =COUNTIF(L10:L30,"A") -> 0 | M34: =COUNTIF(M10:M30,"A") -> 0 | N34: =COUNTIF(N10:N30,"A") -> 0 | O34: =COUNTIF(O10:O30,"A") -> 0 | ... S34: =COUNTIF(S10:S30,"A") -> 0 | T34: =SUM(H34:S34) -> 0
G35: Revision B | H35: =COUNTIF(H10:H30,"B") -> 1 | I35: =COUNTIF(I10:I30,"B") -> 1 | J35: =COUNTIF(J10:J30,"B") -> 1 | K35: =COUNTIF(K10:K30,"B") -> 1 | L35: =COUNTIF(L10:L30,"B") -> 0 | M35: =COUNTIF(M10:M30,"B") -> 0 | N35: =COUNTIF(N10:N30,"B") -> 0 | O35: =COUNTIF(O10:O30,"B") -> 0 | ... S35: =COUNTIF(S10:S30,"B") -> 0 | T35: =SUM(H35:S35) -> 4
G37: Alistamiento | H37: 1 Año
G38: REV | H38: 3 Años
G39: REV A | H39: 6 Años
G40: REV B | H40: 12 Años
H41: AL | I41: AL | J41: REV | K41: AL | L41: AL | M41: A | N41: AL | O41: AL | P41: REV | Q41: AL | R41: AL | S41: B
G42: Años | H42: 1 | I42: 2 | J42: 3 | K42: 4 | L42: 5 | M42: 6 | N42: 7 | O42: 8 | P42: 9 | Q42: 10 | R42: 11 | S42: 12

Sheet LGR RESUMEN VAGONES
G1: Planilla Tipo: MRAM (2)
G3: Avance de Mantenimiento Preventivo
F5: AVANCE DE TAREAS REALIZADAS AL MES DE: | L5: (a)___________________
I6: TIPO DE VEHÍCULO: | L6: Vagones
C8: CANTIDAD DE INTERVENCIONES
A10: Tipo de Revisión | B10: Período | C10: ENERO | E10: FEBRERO | G10: MARZO | I10: ABRIL | K10: MAYO | M10: JUNIO | O10: JULIO | Q10: AGOSTO | S10: SEPTIEMBRE | U10: OCTUBRE | W10: NOVIEMBRE | Y10: DICIEMBRE | AA10: TOTAL
C11: Prog. | D11: Realiz. | E11: Prog. | F11: Realiz. | G11: Prog. | H11: Realiz. | I11: Prog. | J11: Realiz. | K11: Prog. | L11: Realiz. | M11: Prog. | N11: Realiz. | O11: Prog. | P11: Realiz. | Q11: Prog. | R11: Realiz. | S11: Prog. | T11: Realiz. | U11: Prog. | V11: Realiz. | W11: Prog. | X11: Realiz. | Y11: Prog. | Z11: Realiz. | AA11: Prog. | AB11: Realiz.
A12: Alistamiento | B12: 1 Año | C12: 0 | E12: 1 | G12: 0 | I12: 2 | K12: 0 | M12: 0 | O12: 0 | Q12: 0 | S12: 2 | U12: 2 | W12: 0 | Y12: 2 | AA12: =SUM(C12+E12+G12+I12+K12+M12+O12+Q12+S12+U12+W12+Y12) -> 9
A13: Revisión REV | B13: 3 Años | C13: 0 | E13: 0 | G13: 0 | I13: 0 | K13: 1 | M13: 0 | O13: 0 | Q13: 0 | S13: 0 | U13: 0 | W13: 0 | Y13: 0 | AA13: =SUM(C13+E13+G13+I13+K13+M13+O13+Q13+S13+U13+W13+Y13) -> 1
A14: Revisión A | B14: 6 Años | C14: 0 | E14: 0 | G14: 0 | I14: 0 | K14: 0 | M14: 0 | O14: 0 | Q14: 0 | S14: 0 | U14: 0 | W14: 0 | Y14: 0 | AA14: =SUM(C14+E14+G14+I14+K14+M14+O14+Q14+S14+U14+W14+Y14) -> 0
A15: Revisión B | B15: 12 Años | C15: 1 | E15: 1 | G15: 1 | I15: 1 | K15: 0 | M15: 0 | O15: 0 | Q15: 0 | S15: 0 | U15: 0 | W15: 0 | Y15: 0 | AA15: =SUM(C15+E15+G15+I15+K15+M15+O15+Q15+S15+U15+W15+Y15) -> 4

Sheet LGR MR AUXILIAR
G1: Planilla Tipo: MRAM (1)
G3: ='LGR CCEE'!G3:K3 -> Plan de Mantenimiento Preventivo Año: 2026
G4: Kilometraje anual previsto a recorrer: -
E6: TIPO DE VEHÍCULO: | G6: MR Auxiliar
A7: Km Mes:
A8: ='LGR VAGONES'!A8 -> Km. al: 30/09/2025 | C8: Última R.G. | E8: Última Revisión | H8: ='LGR VAGONES'!H8:S8 -> AÑO 2026
A9: Marca-Modelo | B9: Número | C9: Km. | D9: Fecha | E9: Km. | F9: Tipo | G9: Fecha | H9: ENE. | I9: FEB. | J9: MAR. | K9: ABR. | L9: MAY. | M9: JUN. | N9: JUL. | O9: AGO. | P9: SEP. | Q9: OCT. | R9: NOV. | S9: DIC.
A10: Coche Tren de Auxilio | B10: 30 | C10: - | D10: - | E10: - | F10: AB | G10: 45835 | M10: AB
A11: Coche Materfer Frenado | B11: 3548 | C11: - | D11: - | E11: - | F11: AB | G11: 45778 | R11: ABC
A12: Coche Materfer Frenado | B12: 3553 | C12: - | D12: - | E12: - | F12: AB | G12: 45859 | N12: AB
A13: Coche Materfer Frenado | B13: 3657 | C13: - | D13: - | E13: - | F13: AB | G13: 45883 | O13: AB
A14: Coche Materfer Frenado | B14: 3675 | F14: A | G14: 45811 | S14: ABC
A15: Coche Materfer Frenado | B15: 3752 | C15: - | D15: - | E15: - | F15: AB | G15: 45807 | L15: AB
A16: Coche Materfer Frenado | B16: 3761 | C16: - | D16: - | E16: - | F16: ABC | G16: 45832 | N16: AB
A17: Coche Materfer Frenado | B17: 3795 | C17: - | D17: - | E17: - | F17: ABC | G17: 45806 | N17: AB
A18: Locomotora Maniobra | B18: A608 | C18: - | D18: - | E18: - | F18: - | K18: AB
A19: Locomotora Maniobra | B19: A619 | C19: - | D19: - | E19: - | F19: - | O19: AB
A20: Locomotora Maniobra | B20: A620 | C20: - | D20: - | E20: - | F20: - | S20: AB
G22: Revision AB | H22: =COUNTIF(H10:H20,"AB") -> 0 | I22: =COUNTIF(I10:I20,"AB") -> 0 | J22: =COUNTIF(J10:J20,"AB") -> 0 | K22: =COUNTIF(K10:K20,"AB") -> 1 | L22: =COUNTIF(L10:L20,"AB") -> 1 | M22: =COUNTIF(M10:M20,"AB") -> 1 | N22: =COUNTIF(N10:N20,"AB") -> 3 | O22: =COUNTIF(O10:O20,"AB") -> 2 | ... S22: =COUNTIF(S10:S20,"AB") -> 1 | T22: =SUM(H22:S22) -> 9
G23: Revision ABC | H23: =COUNTIF(H10:H20,"ABC") -> 0 | I23: =COUNTIF(I10:I20,"ABC") -> 0 | J23: =COUNTIF(J10:J20,"ABC") -> 0 | K23: =COUNTIF(K10:K20,"ABC") -> 0 | L23: =COUNTIF(L10:L20,"ABC") -> 0 | M23: =COUNTIF(M10:M20,"ABC") -> 0 | N23: =COUNTIF(N10:N20,"ABC") -> 0 | O23: =COUNTIF(O10:O20,"ABC") -> 0 | ... S23: =COUNTIF(S10:S20,"ABC") -> 1 | T23: =SUM(H23:S23) -> 2
A25: Coche Materfer Frenado | B25: 2592 | C25: - | D25: - | E25: - | F25: AB | G25: 45141 | H25: FUERA DEL PARQUE
A26: Coche Materfer Frenado | B26: 2629 | C26: - | D26: - | E26: - | F26: AB | G26: 45025 | H26: FUERA DEL PARQUE
A27: Coche Materfer Frenado | B27: 2633 | C27: - | D27: - | E27: - | F27: AB | G27: 45058 | H27: FUERA DEL PARQUE
A28: Coche Materfer Frenado | B28: 3523 | C28: - | D28: - | E28: - | F28: AB | G28: 45089 | H28: FUERA DEL PARQUE
A29: Coche Materfer Frenado | B29: 3561 | C29: - | D29: - | E29: - | F29: AB | G29: 44862 | H29: FUERA DEL PARQUE

Sheet LGR RESUMEN MR AUXILIAR
G1: Planilla Tipo: MRAM (2)
G3: Avance de Mantenimiento Preventivo
F5: AVANCE DE TAREAS REALIZADAS AL MES DE: | L5: (a)___________________
I6: TIPO DE VEHÍCULO: | L6: MR Auxiliar
C8: CANTIDAD DE INTERVENCIONES
A10: Tipo de Revisión | B10: Período | C10: ENERO | E10: FEBRERO | G10: MARZO | I10: ABRIL | K10: MAYO | M10: JUNIO | O10: JULIO | Q10: AGOSTO | S10: SEPTIEMBRE | U10: OCTUBRE | W10: NOVIEMBRE | Y10: DICIEMBRE | AA10: TOTAL
C11: Prog. | D11: Realiz. | E11: Prog. | F11: Realiz. | G11: Prog. | H11: Realiz. | I11: Prog. | J11: Realiz. | K11: Prog. | L11: Realiz. | M11: Prog. | N11: Realiz. | O11: Prog. | P11: Realiz. | Q11: Prog. | R11: Realiz. | S11: Prog. | T11: Realiz. | U11: Prog. | V11: Realiz. | W11: Prog. | X11: Realiz. | Y11: Prog. | Z11: Realiz. | AA11: Prog. | AB11: Realiz.
A12: Revisión AB | B12: - | C12: 0 | E12: 0 | G12: 0 | I12: 0 | K12: 1 | M12: 1 | O12: 3 | Q12: 1 | S12: 0 | U12: 0 | W12: 0 | Y12: 0 | AA12: =SUM(C12+E12+G12+I12+K12+M12+O12+Q12+S12+U12+W12+Y12) -> 6 | AB12: =+D12+F12+H12+J12+L12+N12+P12+R12+T12+V12+X12+Z12 -> 0
A13: Revisión ABC | B13: - | C13: 0 | E13: 0 | G13: 0 | I13: 0 | K13: 0 | M13: 0 | O13: 0 | Q13: 0 | S13: 0 | U13: 0 | W13: 1 | Y13: 1 | AA13: =SUM(C13+E13+G13+I13+K13+M13+O13+Q13+S13+U13+W13+Y13) -> 2 | AB13: =+D13+F13+H13+J13+L13+N13+P13+R13+T13+V13+X13+Z13 -> 0

Sheet Anexo I
A1: LINEA ROCA
A2: INTERVENCIONES PESADAS QUE NO SE PUEDEN EJECUTAR EN TALLERES PROPIOS
A3: TIPO DE MAT RODANTE | B3: N° | C3: INT. NECESARIA | D3: INT. PROGRAMADA | E3: OBSERVACIONES
A4: GM G22 | B4: A703 | C4: RN4 | D4: ABC + BV
A5: GM GT22 CW-2 | B5: A900 | C5: RN6 | D5: ABC + BV
A6: GM GT22 CW-2 | B6: A909 | C6: RN2 | D6: ABC + BV
A7: GM GT22 CW-2 | B7: A911 | C7: RN6 | D7: ABC + BV
A8: GM GT22 CW-2 | B8: A920 | C8: RN6 | D8: ABC + BV
A9: CCRR Materfer | B9: 2521 | C9: RG | D9: ABC + BV
A10: CCRR Materfer | B10: 2526 | C10: RG | D10: ABC + BV
A11: CCRR Materfer | B11: 2530 | C11: RG | D11: ABC + BV
A12: CCRR Materfer | B12: 2533 | C12: RG | D12: ABC + BV
A13: CCRR Materfer | B13: 2555 | C13: RG | D13: ABC + BV
A14: CCRR Materfer | B14: 2569 | C14: RG | D14: ABC + BV
A15: CCRR Materfer | B15: 2571 | C15: RG | D15: ABC + BV
A16: CCRR Materfer | B16: 2588 | C16: RG | D16: ABC + BV
A17: CCRR Materfer | B17: 2591 | C17: RG | D17: ABC + BV
A18: CCRR Materfer | B18: 2598 | C18: RP | D18: ABC + BV
A19: CCRR Materfer | B19: 2612 | C19: RG | D19: ABC + BV
A20: CCRR Materfer | B20: 2621 | C20: RP | D20: ABC + BV
... A52: CCRR Materfer | B52: 3811 | C52: RG | D52: ABC + BV
A53: Módulo CCEE Toshiba | B53: T06 | C53: RB | D53: MEN + BV
A54: Módulo CCEE Toshiba | B54: T11 | C54: RG | D54: MEN + BV
A55: Módulo CCEE Toshiba | B55: T15 | C55: RG | D55: MEN + BV
A56: Módulo CCEE Toshiba | B56: T22 | C56: RG | D56: MEN + BV
A57: Módulo CCEE Toshiba | B57: T28 | C57: RG | D57: MEN + BV
A58: Módulo CCEE Toshiba | B58: T29 | C58: RB | D58: MEN + BV
A59: Módulo CCEE Toshiba | B59: T31 | C59: RB | D59: MEN + BV
A60: Módulo CCEE Toshiba | B60: T34 | C60: RG | D60: MEN + BV
A61: Módulo CCEE Toshiba | B61: T36 | C61: RB | D61: MEN + BV
A62: Módulo CCEE Toshiba | B62: T43 | C62: RB | D62: MEN + BV
A63: Módulo CCEE Toshiba | B63: T47 | C63: RG | D63: MEN + BV
A64: Módulo CCEE Toshiba | B64: T49 | C64: RG | D64: MEN + BV
... A69: DALIAN CKD8G | B69: G0013 | C69: N2 (720 K) | D69: N1 (360 K) + BV
A70: Módulo CCEE CSR | B70: 14 | C70: DA | D70: BA + BV | E70: BA en Agosto 2026
A71: Módulo CCEE CSR | B71: 37 | C71: DA | D71: BA + BV | E71: BV en Octubre 2026
A72: Módulo CCEE CSR | B72: 40 | C72: DA | D72: BA + BV | E72: BV en Octubre 2026
A73: Módulo CCEE CSR | B73: 46 | C73: DA | D73: AN + BV | E73: BV en Marzo 2026
A74: Módulo CCEE CSR | B74: 74 | C74: DA | D74: AN (04) + BV | E74: BV Vence 03/06/2026
A75: Módulo CCEE CSR | B75: 20 | C75: DA | D75: AN (06) + BV | E75: BV Vence 14/08/2026
...
